
<mujocoinclude >
  <!-- 일반적인 문 규격 : 210-90, 모델 문 사이즈 : 220- 120 -->

    <body name="object">
      <body name="frame_left" pos="0 0 1.1" quat="0.707388 0 0 -0.706825">
          <inertial pos="0.3 0 0" quat="0.5 0.5 0.5 0.5" mass="7.85398" diaginertia="0.923301 0.764585 0.168533" />
          <geom size="0.03 1.1" pos="-0.03 0 0" type="cylinder" rgba="1 1 1 1" group="1" name="r_frame"/>
      </body>
      <body name="frame_right" pos="0 0 1.1" quat="0.707388 0 0 -0.706825">
          <inertial pos="0.3 0 0" quat="0.5 0.5 0.5 0.5" mass="7.85398" diaginertia="0.923301 0.764585 0.168533" />
          <geom size="0.03 1.1" pos="1.23 0 0" type="cylinder" rgba="1 1 1 1" group="1" name="l_frame"/>
          <joint name="hinge" pos="1.23 0 0" axis="0 0 1" range="-2.0 2.0" damping="1" frictionloss="1" limited="true"/>
          <body name="door_body" pos="0.6 0 0">
              <inertial pos="0.0296816 -0.00152345 0" quat="0.701072 0 0 0.713091" mass="2.43455" diaginertia="0.0913751 0.0521615 0.043714" />
              <!-- <joint name="hinge" pos="0.6 0 0" axis="0 0 1" range="-2.0 2.0" damping="1" frictionloss="1" limited="true"/> -->
              <geom size="0.6 0.02 1.05" type="box" friction="1 1 1" group="1" name="panel" material="MatDarkWood"/>
              <body name="latch" pos="-0.5 0 0">
                  <inertial pos="-0.017762 0.0138544 0" quat="0.365653 0.605347 -0.36522 0.605365" mass="0.1" diaginertia="0.0483771 0.0410001 0.0111013" />
                  <geom fromto="0 0 0 0 -0.125 0" size="0.025" type="cylinder" group="1" name="handle_base" material="MatMetal"/>
                  <geom size="0.075 0.015 0.02" pos="0.075 -0.10 0" type="box" group="1" name="handle" material="MatMetal"/>
                  <!-- Don't render the door handle site by default -->
                  <site name="handle" pos="0.125 -0.10 0" size="0.02" rgba="0 0 1 0" />
              </body>
          </body>
      </body>
    </body>
    <site name="bottom_site" pos="0 0 -0.3" rgba="0 0 0 0" size="0.005"/>
    <site name="top_site" pos="0 0 0.3" rgba="0 0 0 0" size="0.005"/>
    <site name="horizontal_radius_site" pos="0.3 0 0" rgba="0 0 0 0" size="0.1"/>
  
</mujocoinclude>


