<mujocoinclude>
  
  

  <!-- <body name="base" childclass="panda" pos="0 0 0"> -->
    
      
    <body name="base_box" pos="0 0 0">
      <inertial pos="0 0 0" quat="1 0 0 0" mass="0.1"/>
      <geom size="0.4 0.3 0.2" pos="0 0 0.3" type="box" group="1" name="huscky" />
    </body>

      
      
      
      
      
    <body name="link0_L" childclass="panda" pos="0.35 -0.215 0.5">
      <inertial mass="0.629769" pos="-0.041018 -0.00014 0.049974"
          fullinertia="0.00315 0.00388 0.004285 8.2904e-7 0.00015 8.2299e-6"/>
      <geom mesh="link0_0" material="off_white" class="visual"/>
      <geom mesh="link0_1" material="black" class="visual"/>
      <geom mesh="link0_2" material="off_white" class="visual"/>
      <geom mesh="link0_3" material="black" class="visual"/>
      <geom mesh="link0_4" material="off_white" class="visual"/>
      <geom mesh="link0_5" material="black" class="visual"/>
      <geom mesh="link0_7" material="white" class="visual"/>
      <geom mesh="link0_8" material="white" class="visual"/>
      <geom mesh="link0_9" material="black" class="visual"/>
      <geom mesh="link0_10" material="off_white" class="visual"/>
      <geom mesh="link0_11" material="white" class="visual"/>
      <geom name = "link0_L_contact" mesh="link0_c" class="collision"/>
        
        
      
      
      
      <body name="link1_L" pos="0 0 0.333" >
      <!-- <body name="link1" pos="0 0 0.333" euler="0 0 0.374"> -->
        <inertial mass="4.970684" pos="0.003875 0.002081 -0.04762"
            fullinertia="0.70337 0.70661 0.0091170 -0.00013900 0.0067720 0.019169"/>
        <joint name="joint1_L" pos="0 0 0" axis="0 0 1" range="-2.7437 2.7437"/>
        <geom material="white" mesh="link1" class="visual"/>
        <geom name = "link1_L_contact" mesh="link1_c" class="collision"/>
        <!-- <body name="link2" euler="0 0 -1.02"> -->
        <body name="link2_L" quat="1 -1 0 0">
        
          <inertial mass="0.646926" pos="-0.003141 -0.02872 0.003495"
              fullinertia="0.0079620 2.8110e-2 2.5995e-2 -3.925e-3 1.0254e-2 7.04e-4"/>
          <joint name="joint2_L" pos="0 0 0" axis="0 0 1" range="-1.7837 1.7837"/>
          <geom material="white" mesh="link2" class="visual"/>
          <geom name = "link2_L_contact" mesh="link2_c" class="collision"/>
          <body name="link3_L" pos="0 -0.316 0" quat="1 1 0 0">
          <!-- <body name="link3" pos="0 -0.316 0" euler="0 0 0.245"> -->
            <joint name="joint3_L" pos="0 0 0" axis="0 0 1" range="-2.9007 2.9007"/>
            <inertial mass="3.228604" pos="2.7518e-2 3.9252e-2 -6.6502e-2"
                fullinertia="3.7242e-2 3.6155e-2 1.083e-2 -4.761e-3 -1.1396e-2 -1.2805e-2"/>
            <geom mesh="link3_0" material="white" class="visual"/>
            <geom mesh="link3_1" material="white" class="visual"/>
            <geom mesh="link3_2" material="white" class="visual"/>
            <geom mesh="link3_3" material="black" class="visual"/>
            <geom name = "link3_L_contact" mesh="link3_c" class="collision"/>
            <body name="link4_L" pos="0.0825 0 0" quat="1 1 0 0">
            <!-- <body name="link4" pos="0.0825 0 0" euler="0 0 -1.51"> -->
              <inertial mass="3.587895" pos="-5.317e-2 1.04419e-1 2.7454e-2"
                  fullinertia="2.5853e-2 1.9552e-2 2.8323e-2 7.796e-3 -1.332e-3 8.641e-3"/>
              <joint name="joint4_L" pos="0 0 0" axis="0 0 1" range="-3.0421 -0.1518"/>
              <geom mesh="link4_0" material="white" class="visual"/>
              <geom mesh="link4_1" material="white" class="visual"/>
              <geom mesh="link4_2" material="black" class="visual"/>
              <geom mesh="link4_3" material="white" class="visual"/>
              <geom name = "link4_L_contact" mesh="link4_c" class="collision"/>
              <body name="link5_L" pos="-0.0825 0.384 0" quat="1 -1 0 0">
              <!-- <body name="link5" pos="-0.0825 0.384 0" euler="0 0 0.0102"> -->
                <inertial mass="1.225946" pos="-1.1953e-2 4.1065e-2 -3.8437e-2"
                    fullinertia="3.5549e-2 2.9474e-2 8.627e-3 -2.117e-3 -4.037e-3 2.29e-4"/>
                <joint name="joint5_L" pos="0 0 0" axis="0 0 1" range="-2.8065 2.8065"/>
                <geom mesh="link5_0" material="black" class="visual"/>
                <geom mesh="link5_1" material="white" class="visual"/>
                <geom mesh="link5_2" material="white" class="visual"/>
                <geom name = "link5_L_contact0" mesh="link5_c0" class="collision"/>
                <geom name = "link5_L_contact1" mesh="link5_c1" class="collision"/>
                <geom name = "link5_L_contact2" mesh="link5_c2" class="collision"/>
                <body name="link6_L" quat="1 1 0 0">
                <!-- <body name="link6" euler="0 0 0.655"> -->
                  <inertial mass="1.666555" pos="6.0149e-2 -1.4117e-2 -1.0517e-2"
                      fullinertia="1.964e-3 4.354e-3 5.433e-3 1.09e-4 -1.158e-3 3.41e-4"/>
                  <joint name="joint6_L" pos="0 0 0" axis="0 0 1" range="0.5445 4.5169"/>
                  <geom mesh="link6_0" material="off_white" class="visual"/>
                  <geom mesh="link6_1" material="white" class="visual"/>
                  <geom mesh="link6_2" material="black" class="visual"/>
                  <geom mesh="link6_3" material="white" class="visual"/>
                  <geom mesh="link6_4" material="white" class="visual"/>
                  <geom mesh="link6_5" material="white" class="visual"/>
                  <geom mesh="link6_6" material="white" class="visual"/>
                  <geom mesh="link6_7" material="light_blue" class="visual"/>
                  <geom mesh="link6_8" material="light_blue" class="visual"/>
                  <geom mesh="link6_9" material="black" class="visual"/>
                  <geom mesh="link6_10" material="black" class="visual"/>
                  <geom mesh="link6_11" material="white" class="visual"/>
                  <geom mesh="link6_12" material="green" class="visual"/>
                  <geom mesh="link6_13" material="white" class="visual"/>
                  <geom mesh="link6_14" material="black" class="visual"/>
                  <geom mesh="link6_15" material="black" class="visual"/>
                  <geom mesh="link6_16" material="white" class="visual"/>
                  <geom name = "link6_L_contact" mesh="link6_c" class="collision"/>
                  <body name="link7_L" pos="0.088 0 0" quat="1 1 0 0">
                  <!-- <body name="link7" pos="0.088 0 0" euler="0 0 0.3"> -->
                    <inertial mass="7.35522e-01" pos="1.0517e-2 -4.252e-3 6.1597e-2"
                        fullinertia="1.2516e-2 1.0027e-2 4.815e-3 -4.28e-4 -1.196e-3 -7.41e-4"/>
                    <joint name="joint7_L" pos="0 0 0" axis="0 0 1" range="-3.0159 3.0159"/>
                    <geom mesh="link7_0" material="white" class="visual"/>
                    <geom mesh="link7_1" material="black" class="visual"/>
                    <geom mesh="link7_2" material="black" class="visual"/>
                    <geom mesh="link7_3" material="black" class="visual"/>
                    <geom mesh="link7_4" material="black" class="visual"/>
                    <geom mesh="link7_5" material="black" class="visual"/>
                    <geom mesh="link7_6" material="black" class="visual"/>
                    <geom mesh="link7_7" material="white" class="visual"/>
                    <site class="FTsensor" name="FTsensor_L" pos="0 0 0.05" type='cylinder' size='0.05 0.05 0.05' rgba='0.9 0.4 0.6 1.0'/>
                    <!-- <site name="FTsensor" pos="0 0 0.05"/> -->
                    <geom name = "link7_L_contact" mesh="link7_c" class="collision"/>
                    <body name="hand_L" pos="0 0 0.107" quat="0.9238795 0 0 -0.3826834">
                      <camera mode="fixed" name="robotview1_L" pos="-0.05 0 -0.02" quat="0 1 0 0"/> 
                      <camera mode="fixed" name="robotview2_L" pos="0.05 0 -0.02" quat="0 1 0 0"/> 
                      
                                    
                      <inertial mass="0.73" pos="-0.01 0 0.03" diaginertia="0.001 0.0025 0.0017"/>
                      <geom mesh="hand_0" material="off_white" class="visual"/>
                      <geom mesh="hand_1" material="black" class="visual"/>
                      <geom mesh="hand_2" material="black" class="visual"/>
                      <geom mesh="hand_3" material="white" class="visual"/>
                      <geom mesh="hand_4" material="off_white" class="visual"/>
                      <geom name = "hand_L_contact" mesh="hand_c" class="collision"/>
                      <body name="left_finger_L" pos="0 0 0.0584">
                        <inertial mass="0.015" pos="0 0 0" diaginertia="2.375e-6 2.375e-6 7.5e-7"/>
                        <!-- <joint name="finger_joint1_L" axis="0 1 0" damping="0.3" type = "slide" class="finger"/> -->
                        <geom mesh="finger_0" material="off_white" class="visual"/>
                        <geom mesh="finger_1" material="black" class="visual"/>

                        <geom name = "finger0_L_contact" mesh="finger_0" class="collision"/>

                        <geom name = "finger_L_contact0" class="fingertip_pad_collision_1"/>
                        <geom name = "finger_L_contact1" class="fingertip_pad_collision_2"/>
                        <geom name = "finger_L_contact2" class="fingertip_pad_collision_3"/>
                        <geom name = "finger_L_contact3" class="fingertip_pad_collision_4"/>
                        <geom name = "finger_L_contact4" class="fingertip_pad_collision_5"/>
                      </body>
                      <body name="right_finger_L" pos="0 0 0.0584" quat="0 0 0 1">
                        <inertial mass="0.015" pos="0 0 0" diaginertia="2.375e-6 2.375e-6 7.5e-7"/>
                        <!-- <joint name="finger_joint2_L" axis="0 1 0" damping="0.3" type = "slide" class="finger"/> -->
                        <geom name = "right_finger1_L" mesh="finger_0" material="off_white" class="visual"/>
                        <geom mesh="finger_0" material="off_white" class="visual"/>
                        <geom mesh="finger_1" material="black" class="visual"/>

                        <geom name = "finger1_L_contact" mesh="finger_0" class="collision"/>

                        <geom name = "finger_L_contact5" class="fingertip_pad_collision_1"/>
                        <geom name = "finger_L_contact6" class="fingertip_pad_collision_2"/>
                        <geom name = "finger_L_contact7" class="fingertip_pad_collision_3"/>
                        <geom name = "finger_L_contact8" class="fingertip_pad_collision_4"/>
                        <geom name = "finger_L_contact9" class="fingertip_pad_collision_5"/>
                      </body>
                    </body>
                  </body>
                </body>
              </body>
            </body>
          </body>
        </body>
      </body>
    </body>

    <body name="link0_R" childclass="panda" pos="0.35 0.215 0.5">
      <inertial mass="0.629769" pos="-0.041018 -0.00014 0.049974"
          fullinertia="0.00315 0.00388 0.004285 8.2904e-7 0.00015 8.2299e-6"/>
      <geom mesh="link0_0" material="off_white" class="visual"/>
      <geom mesh="link0_1" material="black" class="visual"/>
      <geom mesh="link0_2" material="off_white" class="visual"/>
      <geom mesh="link0_3" material="black" class="visual"/>
      <geom mesh="link0_4" material="off_white" class="visual"/>
      <geom mesh="link0_5" material="black" class="visual"/>
      <geom mesh="link0_7" material="white" class="visual"/>
      <geom mesh="link0_8" material="white" class="visual"/>
      <geom mesh="link0_9" material="black" class="visual"/>
      <geom mesh="link0_10" material="off_white" class="visual"/>
      <geom mesh="link0_11" material="white" class="visual"/>
      <geom name = "link0_R_contact" mesh="link0_c" class="collision"/>
        
        
      
      
      
      <body name="link1_R" pos="0 0 0.333" >
      <!-- <body name="link1" pos="0 0 0.333" euler="0 0 0.374"> -->
        <inertial mass="4.970684" pos="0.003875 0.002081 -0.04762"
            fullinertia="0.70337 0.70661 0.0091170 -0.00013900 0.0067720 0.019169"/>
        <joint name="joint1_R" pos="0 0 0" axis="0 0 1" range="-2.7437 2.7437"/>
        <geom material="white" mesh="link1" class="visual"/>
        <geom name = "link1_R_contact" mesh="link1_c" class="collision"/>
        <!-- <body name="link2" euler="0 0 -1.02"> -->
        <body name="link2_R" quat="1 -1 0 0">
        
          <inertial mass="0.646926" pos="-0.003141 -0.02872 0.003495"
              fullinertia="0.0079620 2.8110e-2 2.5995e-2 -3.925e-3 1.0254e-2 7.04e-4"/>
          <joint name="joint2_R" pos="0 0 0" axis="0 0 1" range="-1.7837 1.7837"/>
          <geom material="white" mesh="link2" class="visual"/>
          <geom name = "link2_R_contact" mesh="link2_c" class="collision"/>
          <body name="link3_R" pos="0 -0.316 0" quat="1 1 0 0">
          <!-- <body name="link3" pos="0 -0.316 0" euler="0 0 0.245"> -->
            <joint name="joint3_R" pos="0 0 0" axis="0 0 1" range="-2.9007 2.9007"/>
            <inertial mass="3.228604" pos="2.7518e-2 3.9252e-2 -6.6502e-2"
                fullinertia="3.7242e-2 3.6155e-2 1.083e-2 -4.761e-3 -1.1396e-2 -1.2805e-2"/>
            <geom mesh="link3_0" material="white" class="visual"/>
            <geom mesh="link3_1" material="white" class="visual"/>
            <geom mesh="link3_2" material="white" class="visual"/>
            <geom mesh="link3_3" material="black" class="visual"/>
            <geom name = "link3_R_contact" mesh="link3_c" class="collision"/>
            <body name="link4_R" pos="0.0825 0 0" quat="1 1 0 0">
            <!-- <body name="link4" pos="0.0825 0 0" euler="0 0 -1.51"> -->
              <inertial mass="3.587895" pos="-5.317e-2 1.04419e-1 2.7454e-2"
                  fullinertia="2.5853e-2 1.9552e-2 2.8323e-2 7.796e-3 -1.332e-3 8.641e-3"/>
              <joint name="joint4_R" pos="0 0 0" axis="0 0 1" range="-3.0421 -0.1518"/>
              <geom mesh="link4_0" material="white" class="visual"/>
              <geom mesh="link4_1" material="white" class="visual"/>
              <geom mesh="link4_2" material="black" class="visual"/>
              <geom mesh="link4_3" material="white" class="visual"/>
              <geom name = "link4_R_contact" mesh="link4_c" class="collision"/>
              <body name="link5_R" pos="-0.0825 0.384 0" quat="1 -1 0 0">
              <!-- <body name="link5" pos="-0.0825 0.384 0" euler="0 0 0.0102"> -->
                <inertial mass="1.225946" pos="-1.1953e-2 4.1065e-2 -3.8437e-2"
                    fullinertia="3.5549e-2 2.9474e-2 8.627e-3 -2.117e-3 -4.037e-3 2.29e-4"/>
                <joint name="joint5_R" pos="0 0 0" axis="0 0 1" range="-2.8065 2.8065"/>
                <geom mesh="link5_0" material="black" class="visual"/>
                <geom mesh="link5_1" material="white" class="visual"/>
                <geom mesh="link5_2" material="white" class="visual"/>
                <geom name = "link5_R_contact0" mesh="link5_c0" class="collision"/>
                <geom name = "link5_R_contact1" mesh="link5_c1" class="collision"/>
                <geom name = "link5_R_contact2" mesh="link5_c2" class="collision"/>
                <body name="link6_R" quat="1 1 0 0">
                <!-- <body name="link6" euler="0 0 0.655"> -->
                  <inertial mass="1.666555" pos="6.0149e-2 -1.4117e-2 -1.0517e-2"
                      fullinertia="1.964e-3 4.354e-3 5.433e-3 1.09e-4 -1.158e-3 3.41e-4"/>
                  <joint name="joint6_R" pos="0 0 0" axis="0 0 1" range="0.5445 4.5169"/>
                  <geom mesh="link6_0" material="off_white" class="visual"/>
                  <geom mesh="link6_1" material="white" class="visual"/>
                  <geom mesh="link6_2" material="black" class="visual"/>
                  <geom mesh="link6_3" material="white" class="visual"/>
                  <geom mesh="link6_4" material="white" class="visual"/>
                  <geom mesh="link6_5" material="white" class="visual"/>
                  <geom mesh="link6_6" material="white" class="visual"/>
                  <geom mesh="link6_7" material="light_blue" class="visual"/>
                  <geom mesh="link6_8" material="light_blue" class="visual"/>
                  <geom mesh="link6_9" material="black" class="visual"/>
                  <geom mesh="link6_10" material="black" class="visual"/>
                  <geom mesh="link6_11" material="white" class="visual"/>
                  <geom mesh="link6_12" material="green" class="visual"/>
                  <geom mesh="link6_13" material="white" class="visual"/>
                  <geom mesh="link6_14" material="black" class="visual"/>
                  <geom mesh="link6_15" material="black" class="visual"/>
                  <geom mesh="link6_16" material="white" class="visual"/>
                  <geom name = "link6_R_contact" mesh="link6_c" class="collision"/>
                  <body name="link7_R" pos="0.088 0 0" quat="1 1 0 0">
                  <!-- <body name="link7" pos="0.088 0 0" euler="0 0 0.3"> -->
                    <inertial mass="7.35522e-01" pos="1.0517e-2 -4.252e-3 6.1597e-2"
                        fullinertia="1.2516e-2 1.0027e-2 4.815e-3 -4.28e-4 -1.196e-3 -7.41e-4"/>
                    <joint name="joint7_R" pos="0 0 0" axis="0 0 1" range="-3.0159 3.0159"/>
                    <geom mesh="link7_0" material="white" class="visual"/>
                    <geom mesh="link7_1" material="black" class="visual"/>
                    <geom mesh="link7_2" material="black" class="visual"/>
                    <geom mesh="link7_3" material="black" class="visual"/>
                    <geom mesh="link7_4" material="black" class="visual"/>
                    <geom mesh="link7_5" material="black" class="visual"/>
                    <geom mesh="link7_6" material="black" class="visual"/>
                    <geom mesh="link7_7" material="white" class="visual"/>
                    <site class="FTsensor" name="FTsensor_R" pos="0 0 0.05" type='cylinder' size='0.05 0.05 0.05' rgba='0.9 0.4 0.6 1.0'/>
                    <!-- <site name="FTsensor" pos="0 0 0.05"/> -->
                    <geom name = "link7_R_contact" mesh="link7_c" class="collision"/>
                    <body name="hand_R" pos="0 0 0.107" quat="0.9238795 0 0 -0.3826834">
                      <camera mode="fixed" name="robotview1_R" pos="-0.05 0 -0.02" quat="0 1 0 0"/> 
                      <camera mode="fixed" name="robotview2_R" pos="0.05 0 -0.02" quat="0 1 0 0"/> 
                      
                                    
                      <inertial mass="0.73" pos="-0.01 0 0.03" diaginertia="0.001 0.0025 0.0017"/>
                      <geom mesh="hand_0" material="off_white" class="visual"/>
                      <geom mesh="hand_1" material="black" class="visual"/>
                      <geom mesh="hand_2" material="black" class="visual"/>
                      <geom mesh="hand_3" material="white" class="visual"/>
                      <geom mesh="hand_4" material="off_white" class="visual"/>
                      <geom name = "hand_R_contact" mesh="hand_c" class="collision"/>
                      <body name="left_finger_R" pos="0 0 0.0584">
                        <inertial mass="0.015" pos="0 0 0" diaginertia="2.375e-6 2.375e-6 7.5e-7"/>
                        <!-- <joint name="finger_joint1_R" axis="0 1 0" damping="0.3" type = "slide" class="finger"/> -->
                        <geom mesh="finger_0" material="off_white" class="visual"/>
                        <geom mesh="finger_1" material="black" class="visual"/>

                        <geom name = "finger0_R_contact" mesh="finger_0" class="collision"/>

                        <geom name = "finger_R_contact0" class="fingertip_pad_collision_1"/>
                        <geom name = "finger_R_contact1" class="fingertip_pad_collision_2"/>
                        <geom name = "finger_R_contact2" class="fingertip_pad_collision_3"/>
                        <geom name = "finger_R_contact3" class="fingertip_pad_collision_4"/>
                        <geom name = "finger_R_contact4" class="fingertip_pad_collision_5"/>
                      </body>
                      <body name="right_finger_R" pos="0 0 0.0584" quat="0 0 0 1">
                        <inertial mass="0.015" pos="0 0 0" diaginertia="2.375e-6 2.375e-6 7.5e-7"/>
                        <!-- <joint name="finger_joint2_R" axis="0 1 0" damping="0.3" type = "slide" class="finger"/> -->
                        <geom name = "right_finger1_R" mesh="finger_0" material="off_white" class="visual"/>
                        <geom mesh="finger_0" material="off_white" class="visual"/>
                        <geom mesh="finger_1" material="black" class="visual"/>

                        <geom name = "finger1_R_contact" mesh="finger_0" class="collision"/>

                        <geom name = "finger_R_contact5" class="fingertip_pad_collision_1"/>
                        <geom name = "finger_R_contact6" class="fingertip_pad_collision_2"/>
                        <geom name = "finger_R_contact7" class="fingertip_pad_collision_3"/>
                        <geom name = "finger_R_contact8" class="fingertip_pad_collision_4"/>
                        <geom name = "finger_R_contact9" class="fingertip_pad_collision_5"/>
                      </body>
                    </body>
                  </body>
                </body>
              </body>
            </body>
          </body>
        </body>
      </body>
    </body>


  <!-- </body> -->

  

</mujocoinclude>
